Workbook

Sheet Start Here
B1: Business Control Center
B2: Bookkeeping and management workbook for a Sri Lankan service business. Financial year April 2026 – March 2027.
B4: HOW THE WORKBOOK FITS TOGETHER
B5: 1. Setup | C5: Fill once: business details, opening balances, your categories.
B6: 2. Transactions | C6: THE ONLY PLACE YOU TYPE MONEY. Every payment in or out, one row each. Everything else is calculated from here.
B7: 3. Invoices | C7: Every invoice you send, and whether it is paid. Shows who owes you.
B8: 4. Clients | C8: Your client list, with revenue and amount owed per client.
B9: 5. Monthly P&L | C9: Automatic. Profit and loss by month: revenue, costs, profit, margins.
B10: 6. Cash Flow | C10: Automatic. Cash in and out by month. Closing cash must match your bank.
B11: 7. Dashboard | C11: Automatic. One-page health check for any month, with warning signs.
B12: 8. Service Pricing | C12: Work out what each service really earns and what to charge.
B13: 9. Forecast | C13: Plan revenue and costs for Oct 2026 – Mar 2027 and compare with actuals.
B14: 10. Sales Pipeline | C14: Every lead, until it is won or lost.
B15: 11. Weekly Review | C15: Your 30-minute weekly check-in, one row per week of the 90 days.
B16: 12. 90-Day Plan | C16: Your crash-course task list, with progress tracking.
B17: 13. Tax Calendar | C17: Sri Lankan deadlines and thresholds to confirm with your accountant.
B19: COLOUR LEGEND
B20: Yellow cell / blue text | C20: You type here.
B21: Grey cell / black text | C21: Calculated automatically. Do not type over it.
B22: Green text | C22: Pulled from another sheet.
B23: Orange row | C23: An example to show the format. Overwrite or delete it.
B25: THE 5 GOLDEN RULES
B26: Rule 1 | C26: Business money and personal money never mix. Pay yourself a fixed salary (Owner drawings) instead of taking cash when needed.
B27: Rule 2 | C27: Every rupee gets a row. If it left or entered an account, it goes on Transactions with a category.
B28: Rule 3 | C28: No receipt, no record. Photograph every receipt the same day; note its number in the Reference column.
B29: Rule 4 | C29: Match the bank every month. Cash Flow closing cash must equal the real balance (Difference row = 0).
B30: Rule 5 | C30: Look at the numbers weekly. 30 minutes every week on the Weekly Review beats 3 days of panic at tax time.
B32: DAILY 10-MINUTE ROUTINE | C32: Open the bank app → enter yesterday's payments on Transactions → save receipts → mark any paid invoices.
B33: MONTHLY CLOSE (1–2 h) | C33: Enter everything → type real balances on Cash Flow row 23 → fix differences → chase overdue invoices → read P&L and Dashboard → move tax reserve.

Sheet Setup
A1: Setup: your business profile, accounts and categories
A2: Fill the yellow cells once. Everything else in the workbook reads from here.
A3: BUSINESS PROFILE
A4: Business name | B4: Your Business Name | D4: Trading name used on invoices.
A5: Owner(s) | B5: Owner name | D5: Who owns the business.
A6: Financial year starts | B6: 46113 | D6: Sri Lanka tax year runs 1 April – 31 March. The P&L and Cash Flow start here.
A7: Currency | B7: LKR (Rs) | D7: All amounts in Sri Lankan rupees.
A8: Tax reserve (% of net profit) | B8: 0.1 | D8: Assumption: move this % of each month's profit to a separate tax savings account. Ask your accountant for the right % for you.
A9: Target owner salary per month (Rs) | B9: 0 | D9: Fixed amount you pay yourself each month (set this in Week 4).
A10: Default invoice payment terms (days) | B10: 14 | D10: Used on the Invoices sheet when terms are left blank.
A12: MONEY ACCOUNTS (where money is kept)
A13: Account name | B13: Opening balance on FY start (Rs) | C13: Account number (last 4) | D13: Notes
A14: Business bank account | B14: 0 | D14: Main account for the business. All client payments should come here.
A15: Cash in hand | B15: 0 | D15: Physical cash kept for the business.
A16: Owner personal account (temporary) | B16: 0 | D16: Only while business money still passes through a personal account. Aim to stop using it.
A17: Tax savings account | B17: 0 | D17: Separate savings account where you keep the tax reserve.
A20: Total opening balance | B20: =SUM(B14:B19)
A22: CATEGORIES (the chart of accounts)
A23: Category | B23: Type (do not change) | C23: Report section | D23: What goes here
A24: Service fees – main service | B24: Income | C24: Revenue | D24: Fees for your main service. Rename to your service, e.g. "Web design projects".
A25: Service fees – second service | B25: Income | C25: Revenue | D25: Rename to your second service, or leave unused.
A26: Retainer / monthly fees | B26: Income | C26: Revenue | D26: Fixed monthly fees from ongoing clients.
A27: Other income | B27: Income | C27: Revenue | D27: Small one-off income (interest, sale of scrap, etc.).
B28: Income | C28: Revenue | D28: Spare: type a new income category here.
A29: Freelancers & subcontractors | B29: Direct Cost | C29: Cost of delivering services | D29: People paid to deliver client work.
A30: Project staff wages | B30: Direct Cost | C30: Cost of delivering services | D30: Wages of staff who do client work.
A31: Project tools & materials | B31: Direct Cost | C31: Cost of delivering services | D31: Software, materials or printing bought for a specific client job.
A32: Project travel | B32: Direct Cost | C32: Cost of delivering services | D32: Travel to deliver client work.
B33: Direct Cost | C33: Cost of delivering services | D33: Spare: type a new direct cost here.
A34: Salaries – admin & sales | B34: Operating Expense | C34: Overheads (running costs) | D34: Staff not directly doing client work.
A35: EPF / ETF (employer share) | B35: Operating Expense | C35: Overheads (running costs) | D35: Employer EPF 12% and ETF 3% on staff salaries.
A36: Rent | B36: Operating Expense | C36: Overheads (running costs) | D36: Office or workspace rent.
A37: Electricity & water | B37: Operating Expense | C37: Overheads (running costs) | D37: Utility bills.
A38: Internet & phone | B38: Operating Expense | C38: Overheads (running costs) | D38: Broadband, mobile bills, data.
A39: Software & subscriptions | B39: Operating Expense | C39: Overheads (running costs) | D39: Tools used to run the business (not for one client).
A40: Marketing & advertising | B40: Operating Expense | C40: Overheads (running costs) | D40: Ads, printing, sponsored posts, website.
A41: Professional fees | B41: Operating Expense | C41: Overheads (running costs) | D41: Accountant, lawyer, consultants.
A42: Bank charges | B42: Operating Expense | C42: Overheads (running costs) | D42: Fees, card charges, transfer fees.
A43: Transport & fuel | B43: Operating Expense | C43: Overheads (running costs) | D43: Business travel not linked to one client.
A44: Office supplies | B44: Operating Expense | C44: Overheads (running costs) | D44: Stationery, small office items.
...

Sheet Transactions
A1: Transactions: the cash book (every rupee in and out)
A2: One row per payment. Yellow = you type. Grey = calculated. Enter money IN or money OUT, never both on one row.
A3: Legend: | B3: Blue text = you type · Grey = automatic · Orange = example row (overwrite it)
A4: Date | B4: Description | C4: Client / Supplier | D4: Category | E4: Money IN (Rs) | F4: Money OUT (Rs) | G4: Account | H4: Method | I4: Reference (invoice / receipt no.) | J4: Receipt saved? | K4: Type (auto) | L4: Month (auto) | M4: Net (auto) | N4: Notes
A5: 46115 | B5: EXAMPLE: Website project, 50% advance | C5: ABC Holdings (Pvt) Ltd | D5: Service fees – main service | E5: 150000 | G5: Business bank account | H5: Bank transfer | I5: INV-001 | J5: Yes | K5: =IF(D5="","",IFERROR(INDEX(Setup!$B$24:$B$59,MATCH(D5,Setup!$A$24:$A$59,0)),"Check category")) | L5: =IF(A5="","",DATE(YEAR(A5),MONTH(A5),1)) | M5: =IF(AND(E5="",F5=""),"",N(E5)-N(F5)) | N5: Example row: replace or delete it
K6: =IF(D6="","",IFERROR(INDEX(Setup!$B$24:$B$59,MATCH(D6,Setup!$A$24:$A$59,0)),"Check category")) | L6: =IF(A6="","",DATE(YEAR(A6),MONTH(A6),1)) | M6: =IF(AND(E6="",F6=""),"",N(E6)-N(F6))
K7: =IF(D7="","",IFERROR(INDEX(Setup!$B$24:$B$59,MATCH(D7,Setup!$A$24:$A$59,0)),"Check category")) | L7: =IF(A7="","",DATE(YEAR(A7),MONTH(A7),1)) | M7: =IF(AND(E7="",F7=""),"",N(E7)-N(F7))
K8: =IF(D8="","",IFERROR(INDEX(Setup!$B$24:$B$59,MATCH(D8,Setup!$A$24:$A$59,0)),"Check category")) | L8: =IF(A8="","",DATE(YEAR(A8),MONTH(A8),1)) | M8: =IF(AND(E8="",F8=""),"",N(E8)-N(F8))
K9: =IF(D9="","",IFERROR(INDEX(Setup!$B$24:$B$59,MATCH(D9,Setup!$A$24:$A$59,0)),"Check category")) | L9: =IF(A9="","",DATE(YEAR(A9),MONTH(A9),1)) | M9: =IF(AND(E9="",F9=""),"",N(E9)-N(F9))
K10: =IF(D10="","",IFERROR(INDEX(Setup!$B$24:$B$59,MATCH(D10,Setup!$A$24:$A$59,0)),"Check category")) | L10: =IF(A10="","",DATE(YEAR(A10),MONTH(A10),1)) | M10: =IF(AND(E10="",F10=""),"",N(E10)-N(F10))
K11: =IF(D11="","",IFERROR(INDEX(Setup!$B$24:$B$59,MATCH(D11,Setup!$A$24:$A$59,0)),"Check category")) | L11: =IF(A11="","",DATE(YEAR(A11),MONTH(A11),1)) | M11: =IF(AND(E11="",F11=""),"",N(E11)-N(F11))
K12: =IF(D12="","",IFERROR(INDEX(Setup!$B$24:$B$59,MATCH(D12,Setup!$A$24:$A$59,0)),"Check category")) | L12: =IF(A12="","",DATE(YEAR(A12),MONTH(A12),1)) | M12: =IF(AND(E12="",F12=""),"",N(E12)-N(F12))
K13: =IF(D13="","",IFERROR(INDEX(Setup!$B$24:$B$59,MATCH(D13,Setup!$A$24:$A$59,0)),"Check category")) | L13: =IF(A13="","",DATE(YEAR(A13),MONTH(A13),1)) | M13: =IF(AND(E13="",F13=""),"",N(E13)-N(F13))
K14: =IF(D14="","",IFERROR(INDEX(Setup!$B$24:$B$59,MATCH(D14,Setup!$A$24:$A$59,0)),"Check category")) | L14: =IF(A14="","",DATE(YEAR(A14),MONTH(A14),1)) | M14: =IF(AND(E14="",F14=""),"",N(E14)-N(F14))
K15: =IF(D15="","",IFERROR(INDEX(Setup!$B$24:$B$59,MATCH(D15,Setup!$A$24:$A$59,0)),"Check category")) | L15: =IF(A15="","",DATE(YEAR(A15),MONTH(A15),1)) | M15: =IF(AND(E15="",F15=""),"",N(E15)-N(F15))
K16: =IF(D16="","",IFERROR(INDEX(Setup!$B$24:$B$59,MATCH(D16,Setup!$A$24:$A$59,0)),"Check category")) | L16: =IF(A16="","",DATE(YEAR(A16),MONTH(A16),1)) | M16: =IF(AND(E16="",F16=""),"",N(E16)-N(F16))
K17: =IF(D17="","",IFERROR(INDEX(Setup!$B$24:$B$59,MATCH(D17,Setup!$A$24:$A$59,0)),"Check category")) | L17: =IF(A17="","",DATE(YEAR(A17),MONTH(A17),1)) | M17: =IF(AND(E17="",F17=""),"",N(E17)-N(F17))
... K1504: =IF(D1504="","",IFERROR(INDEX(Setup!$B$24:$B$59,MATCH(D1504,Setup!$A$24:$A$59,0)),"Check category")) | L1504: =IF(A1504="","",DATE(YEAR(A1504),MONTH(A1504),1)) | M1504: =IF(AND(E1504="",F1504=""),"",N(E1504)-N(F1504))

Sheet Invoices
A1: Invoices: who owes us money?
A2: Add every invoice you send. When it is paid, fill Amount paid + Paid date, AND record the payment on Transactions.
A3: Total outstanding: | C3: =SUM(I5:I404) | D3: Overdue: | F3: =SUMIFS(I5:I404,K5:K404,"Overdue")
A4: Invoice no. | B4: Client | C4: Service | D4: Issue date | E4: Terms (days) | F4: Due date (auto) | G4: Amount (Rs) | H4: Amount paid (Rs) | I4: Balance due (auto) | J4: Paid date | K4: Status (auto) | L4: Days overdue (auto) | M4: Notes / follow-up
A5: INV-001 | B5: ABC Holdings (Pvt) Ltd | C5: Website project | D5: 46113 | E5: 14 | F5: =IF(D5="","",D5+IF(E5="",Setup!$B$10,E5)) | G5: 300000 | H5: 150000 | I5: =IF(G5="","",G5-N(H5)) | K5: =IF(G5="","",IF(I5<=0,"Paid",IF(TODAY()>F5,"Overdue","Open"))) | L5: =IF(K5="Overdue",TODAY()-F5,"") | M5: Example row: replace or delete
F6: =IF(D6="","",D6+IF(E6="",Setup!$B$10,E6)) | I6: =IF(G6="","",G6-N(H6)) | K6: =IF(G6="","",IF(I6<=0,"Paid",IF(TODAY()>F6,"Overdue","Open"))) | L6: =IF(K6="Overdue",TODAY()-F6,"")
F7: =IF(D7="","",D7+IF(E7="",Setup!$B$10,E7)) | I7: =IF(G7="","",G7-N(H7)) | K7: =IF(G7="","",IF(I7<=0,"Paid",IF(TODAY()>F7,"Overdue","Open"))) | L7: =IF(K7="Overdue",TODAY()-F7,"")
F8: =IF(D8="","",D8+IF(E8="",Setup!$B$10,E8)) | I8: =IF(G8="","",G8-N(H8)) | K8: =IF(G8="","",IF(I8<=0,"Paid",IF(TODAY()>F8,"Overdue","Open"))) | L8: =IF(K8="Overdue",TODAY()-F8,"")
F9: =IF(D9="","",D9+IF(E9="",Setup!$B$10,E9)) | I9: =IF(G9="","",G9-N(H9)) | K9: =IF(G9="","",IF(I9<=0,"Paid",IF(TODAY()>F9,"Overdue","Open"))) | L9: =IF(K9="Overdue",TODAY()-F9,"")
F10: =IF(D10="","",D10+IF(E10="",Setup!$B$10,E10)) | I10: =IF(G10="","",G10-N(H10)) | K10: =IF(G10="","",IF(I10<=0,"Paid",IF(TODAY()>F10,"Overdue","Open"))) | L10: =IF(K10="Overdue",TODAY()-F10,"")
F11: =IF(D11="","",D11+IF(E11="",Setup!$B$10,E11)) | I11: =IF(G11="","",G11-N(H11)) | K11: =IF(G11="","",IF(I11<=0,"Paid",IF(TODAY()>F11,"Overdue","Open"))) | L11: =IF(K11="Overdue",TODAY()-F11,"")
F12: =IF(D12="","",D12+IF(E12="",Setup!$B$10,E12)) | I12: =IF(G12="","",G12-N(H12)) | K12: =IF(G12="","",IF(I12<=0,"Paid",IF(TODAY()>F12,"Overdue","Open"))) | L12: =IF(K12="Overdue",TODAY()-F12,"")
F13: =IF(D13="","",D13+IF(E13="",Setup!$B$10,E13)) | I13: =IF(G13="","",G13-N(H13)) | K13: =IF(G13="","",IF(I13<=0,"Paid",IF(TODAY()>F13,"Overdue","Open"))) | L13: =IF(K13="Overdue",TODAY()-F13,"")
F14: =IF(D14="","",D14+IF(E14="",Setup!$B$10,E14)) | I14: =IF(G14="","",G14-N(H14)) | K14: =IF(G14="","",IF(I14<=0,"Paid",IF(TODAY()>F14,"Overdue","Open"))) | L14: =IF(K14="Overdue",TODAY()-F14,"")
F15: =IF(D15="","",D15+IF(E15="",Setup!$B$10,E15)) | I15: =IF(G15="","",G15-N(H15)) | K15: =IF(G15="","",IF(I15<=0,"Paid",IF(TODAY()>F15,"Overdue","Open"))) | L15: =IF(K15="Overdue",TODAY()-F15,"")
F16: =IF(D16="","",D16+IF(E16="",Setup!$B$10,E16)) | I16: =IF(G16="","",G16-N(H16)) | K16: =IF(G16="","",IF(I16<=0,"Paid",IF(TODAY()>F16,"Overdue","Open"))) | L16: =IF(K16="Overdue",TODAY()-F16,"")
F17: =IF(D17="","",D17+IF(E17="",Setup!$B$10,E17)) | I17: =IF(G17="","",G17-N(H17)) | K17: =IF(G17="","",IF(I17<=0,"Paid",IF(TODAY()>F17,"Overdue","Open"))) | L17: =IF(K17="Overdue",TODAY()-F17,"")
... F404: =IF(D404="","",D404+IF(E404="",Setup!$B$10,E404)) | I404: =IF(G404="","",G404-N(H404)) | K404: =IF(G404="","",IF(I404<=0,"Paid",IF(TODAY()>F404,"Overdue","Open"))) | L404: =IF(K404="Overdue",TODAY()-F404,"")

Sheet Clients
A1: Clients: who pays us, and how much?
A2: Type each client once, spelled exactly as on Transactions and Invoices. Revenue and balances fill in automatically.
A3: Red share = this client is more than 30% of revenue (concentration risk).
A4: Client name | B4: Contact person | C4: Phone / email | D4: Main service | E4: Client since | F4: Revenue this FY (auto) | G4: Share of revenue (auto) | H4: Owed to us (auto) | I4: Notes
A5: ABC Holdings (Pvt) Ltd | B5: Mr. Perera | C5: perera@example.lk | D5: Website project | E5: 46113 | F5: =IF(A5="","",SUMIFS(Transactions!$E$5:$E$1504,Transactions!$C$5:$C$1504,A5,Transactions!$K$5:$K$1504,"Income")-SUMIFS(Transactions!$F$5:$F$1504,Transactions!$C$5:$C$1504,A5,Transactions!$K$5:$K$1504,"Income")) | G5: =IF(A5="","",IF('Monthly P&L'!$N$11=0,0,F5/'Monthly P&L'!$N$11)) | H5: =IF(A5="","",SUMIFS(Invoices!$I$5:$I$404,Invoices!$B$5:$B$404,A5)) | I5: Example row: replace or delete
F6: =IF(A6="","",SUMIFS(Transactions!$E$5:$E$1504,Transactions!$C$5:$C$1504,A6,Transactions!$K$5:$K$1504,"Income")-SUMIFS(Transactions!$F$5:$F$1504,Transactions!$C$5:$C$1504,A6,Transactions!$K$5:$K$1504,"Income")) | G6: =IF(A6="","",IF('Monthly P&L'!$N$11=0,0,F6/'Monthly P&L'!$N$11)) | H6: =IF(A6="","",SUMIFS(Invoices!$I$5:$I$404,Invoices!$B$5:$B$404,A6))
F7: =IF(A7="","",SUMIFS(Transactions!$E$5:$E$1504,Transactions!$C$5:$C$1504,A7,Transactions!$K$5:$K$1504,"Income")-SUMIFS(Transactions!$F$5:$F$1504,Transactions!$C$5:$C$1504,A7,Transactions!$K$5:$K$1504,"Income")) | G7: =IF(A7="","",IF('Monthly P&L'!$N$11=0,0,F7/'Monthly P&L'!$N$11)) | H7: =IF(A7="","",SUMIFS(Invoices!$I$5:$I$404,Invoices!$B$5:$B$404,A7))
F8: =IF(A8="","",SUMIFS(Transactions!$E$5:$E$1504,Transactions!$C$5:$C$1504,A8,Transactions!$K$5:$K$1504,"Income")-SUMIFS(Transactions!$F$5:$F$1504,Transactions!$C$5:$C$1504,A8,Transactions!$K$5:$K$1504,"Income")) | G8: =IF(A8="","",IF('Monthly P&L'!$N$11=0,0,F8/'Monthly P&L'!$N$11)) | H8: =IF(A8="","",SUMIFS(Invoices!$I$5:$I$404,Invoices!$B$5:$B$404,A8))
F9: =IF(A9="","",SUMIFS(Transactions!$E$5:$E$1504,Transactions!$C$5:$C$1504,A9,Transactions!$K$5:$K$1504,"Income")-SUMIFS(Transactions!$F$5:$F$1504,Transactions!$C$5:$C$1504,A9,Transactions!$K$5:$K$1504,"Income")) | G9: =IF(A9="","",IF('Monthly P&L'!$N$11=0,0,F9/'Monthly P&L'!$N$11)) | H9: =IF(A9="","",SUMIFS(Invoices!$I$5:$I$404,Invoices!$B$5:$B$404,A9))
F10: =IF(A10="","",SUMIFS(Transactions!$E$5:$E$1504,Transactions!$C$5:$C$1504,A10,Transactions!$K$5:$K$1504,"Income")-SUMIFS(Transactions!$F$5:$F$1504,Transactions!$C$5:$C$1504,A10,Transactions!$K$5:$K$1504,"Income")) | G10: =IF(A10="","",IF('Monthly P&L'!$N$11=0,0,F10/'Monthly P&L'!$N$11)) | H10: =IF(A10="","",SUMIFS(Invoices!$I$5:$I$404,Invoices!$B$5:$B$404,A10))
F11: =IF(A11="","",SUMIFS(Transactions!$E$5:$E$1504,Transactions!$C$5:$C$1504,A11,Transactions!$K$5:$K$1504,"Income")-SUMIFS(Transactions!$F$5:$F$1504,Transactions!$C$5:$C$1504,A11,Transactions!$K$5:$K$1504,"Income")) | G11: =IF(A11="","",IF('Monthly P&L'!$N$11=0,0,F11/'Monthly P&L'!$N$11)) | H11: =IF(A11="","",SUMIFS(Invoices!$I$5:$I$404,Invoices!$B$5:$B$404,A11))
F12: =IF(A12="","",SUMIFS(Transactions!$E$5:$E$1504,Transactions!$C$5:$C$1504,A12,Transactions!$K$5:$K$1504,"Income")-SUMIFS(Transactions!$F$5:$F$1504,Transactions!$C$5:$C$1504,A12,Transactions!$K$5:$K$1504,"Income")) | G12: =IF(A12="","",IF('Monthly P&L'!$N$11=0,0,F12/'Monthly P&L'!$N$11)) | H12: =IF(A12="","",SUMIFS(Invoices!$I$5:$I$404,Invoices!$B$5:$B$404,A12))
F13: =IF(A13="","",SUMIFS(Transactions!$E$5:$E$1504,Transactions!$C$5:$C$1504,A13,Transactions!$K$5:$K$1504,"Income")-SUMIFS(Transactions!$F$5:$F$1504,Transactions!$C$5:$C$1504,A13,Transactions!$K$5:$K$1504,"Income")) | G13: =IF(A13="","",IF('Monthly P&L'!$N$11=0,0,F13/'Monthly P&L'!$N$11)) | H13: =IF(A13="","",SUMIFS(Invoices!$I$5:$I$404,Invoices!$B$5:$B$404,A13))
F14: =IF(A14="","",SUMIFS(Transactions!$E$5:$E$1504,Transactions!$C$5:$C$1504,A14,Transactions!$K$5:$K$1504,"Income")-SUMIFS(Transactions!$F$5:$F$1504,Transactions!$C$5:$C$1504,A14,Transactions!$K$5:$K$1504,"Income")) | G14: =IF(A14="","",IF('Monthly P&L'!$N$11=0,0,F14/'Monthly P&L'!$N$11)) | H14: =IF(A14="","",SUMIFS(Invoices!$I$5:$I$404,Invoices!$B$5:$B$404,A14))
F15: =IF(A15="","",SUMIFS(Transactions!$E$5:$E$1504,Transactions!$C$5:$C$1504,A15,Transactions!$K$5:$K$1504,"Income")-SUMIFS(Transactions!$F$5:$F$1504,Transactions!$C$5:$C$1504,A15,Transactions!$K$5:$K$1504,"Income")) | G15: =IF(A15="","",IF('Monthly P&L'!$N$11=0,0,F15/'Monthly P&L'!$N$11)) | H15: =IF(A15="","",SUMIFS(Invoices!$I$5:$I$404,Invoices!$B$5:$B$404,A15))
F16: =IF(A16="","",SUMIFS(Transactions!$E$5:$E$1504,Transactions!$C$5:$C$1504,A16,Transactions!$K$5:$K$1504,"Income")-SUMIFS(Transactions!$F$5:$F$1504,Transactions!$C$5:$C$1504,A16,Transactions!$K$5:$K$1504,"Income")) | G16: =IF(A16="","",IF('Monthly P&L'!$N$11=0,0,F16/'Monthly P&L'!$N$11)) | H16: =IF(A16="","",SUMIFS(Invoices!$I$5:$I$404,Invoices!$B$5:$B$404,A16))
F17: =IF(A17="","",SUMIFS(Transactions!$E$5:$E$1504,Transactions!$C$5:$C$1504,A17,Transactions!$K$5:$K$1504,"Income")-SUMIFS(Transactions!$F$5:$F$1504,Transactions!$C$5:$C$1504,A17,Transactions!$K$5:$K$1504,"Income")) | G17: =IF(A17="","",IF('Monthly P&L'!$N$11=0,0,F17/'Monthly P&L'!$N$11)) | H17: =IF(A17="","",SUMIFS(Invoices!$I$5:$I$404,Invoices!$B$5:$B$404,A17))
... F104: =IF(A104="","",SUMIFS(Transactions!$E$5:$E$1504,Transactions!$C$5:$C$1504,A104,Transactions!$K$5:$K$1504,"Income")-SUMIFS(Transactions!$F$5:$F$1504,Transactions!$C$5:$C$1504,A104,Transactions!$K$5:$K$1504,"Income")) | G104: =IF(A104="","",IF('Monthly P&L'!$N$11=0,0,F104/'Monthly P&L'!$N$11)) | H104: =IF(A104="","",SUMIFS(Invoices!$I$5:$I$404,Invoices!$B$5:$B$404,A104))

Sheet Monthly P&L
A1: Profit & Loss: did we make money each month?
A2: Fully automatic from the Transactions sheet. Financial year April–March.
A4: Line item (Rs) | B4: =Setup!$B$6 | C4: =EDATE(B4,1) | D4: =EDATE(C4,1) | E4: =EDATE(D4,1) | F4: =EDATE(E4,1) | G4: =EDATE(F4,1) | H4: =EDATE(G4,1) | I4: =EDATE(H4,1) | J4: =EDATE(I4,1) | ... M4: =EDATE(L4,1) | N4: FY total
A5: REVENUE (sales)
A6: =IF(Setup!$A$24="","",Setup!$A$24) | B6: =IF($A6="",0,SUMIFS(Transactions!$E$5:$E$1504,Transactions!$D$5:$D$1504,$A6,Transactions!$L$5:$L$1504,B$4)-SUMIFS(Transactions!$F$5:$F$1504,Transactions!$D$5:$D$1504,$A6,Transactions!$L$5:$L$1504,B$4)) | C6: =IF($A6="",0,SUMIFS(Transactions!$E$5:$E$1504,Transactions!$D$5:$D$1504,$A6,Transactions!$L$5:$L$1504,C$4)-SUMIFS(Transactions!$F$5:$F$1504,Transactions!$D$5:$D$1504,$A6,Transactions!$L$5:$L$1504,C$4)) | D6: =IF($A6="",0,SUMIFS(Transactions!$E$5:$E$1504,Transactions!$D$5:$D$1504,$A6,Transactions!$L$5:$L$1504,D$4)-SUMIFS(Transactions!$F$5:$F$1504,Transactions!$D$5:$D$1504,$A6,Transactions!$L$5:$L$1504,D$4)) | E6: =IF($A6="",0,SUMIFS(Transactions!$E$5:$E$1504,Transactions!$D$5:$D$1504,$A6,Transactions!$L$5:$L$1504,E$4)-SUMIFS(Transactions!$F$5:$F$1504,Transactions!$D$5:$D$1504,$A6,Transactions!$L$5:$L$1504,E$4)) | F6: =IF($A6="",0,SUMIFS(Transactions!$E$5:$E$1504,Transactions!$D$5:$D$1504,$A6,Transactions!$L$5:$L$1504,F$4)-SUMIFS(Transactions!$F$5:$F$1504,Transactions!$D$5:$D$1504,$A6,Transactions!$L$5:$L$1504,F$4)) | G6: =IF($A6="",0,SUMIFS(Transactions!$E$5:$E$1504,Transactions!$D$5:$D$1504,$A6,Transactions!$L$5:$L$1504,G$4)-SUMIFS(Transactions!$F$5:$F$1504,Transactions!$D$5:$D$1504,$A6,Transactions!$L$5:$L$1504,G$4)) | H6: =IF($A6="",0,SUMIFS(Transactions!$E$5:$E$1504,Transactions!$D$5:$D$1504,$A6,Transactions!$L$5:$L$1504,H$4)-SUMIFS(Transactions!$F$5:$F$1504,Transactions!$D$5:$D$1504,$A6,Transactions!$L$5:$L$1504,H$4)) | I6: =IF($A6="",0,SUMIFS(Transactions!$E$5:$E$1504,Transactions!$D$5:$D$1504,$A6,Transactions!$L$5:$L$1504,I$4)-SUMIFS(Transactions!$F$5:$F$1504,Transactions!$D$5:$D$1504,$A6,Transactions!$L$5:$L$1504,I$4)) | ... M6: =IF($A6="",0,SUMIFS(Transactions!$E$5:$E$1504,Transactions!$D$5:$D$1504,$A6,Transactions!$L$5:$L$1504,M$4)-SUMIFS(Transactions!$F$5:$F$1504,Transactions!$D$5:$D$1504,$A6,Transactions!$L$5:$L$1504,M$4)) | N6: =SUM(B6:M6)
A7: =IF(Setup!$A$25="","",Setup!$A$25) | B7: =IF($A7="",0,SUMIFS(Transactions!$E$5:$E$1504,Transactions!$D$5:$D$1504,$A7,Transactions!$L$5:$L$1504,B$4)-SUMIFS(Transactions!$F$5:$F$1504,Transactions!$D$5:$D$1504,$A7,Transactions!$L$5:$L$1504,B$4)) | C7: =IF($A7="",0,SUMIFS(Transactions!$E$5:$E$1504,Transactions!$D$5:$D$1504,$A7,Transactions!$L$5:$L$1504,C$4)-SUMIFS(Transactions!$F$5:$F$1504,Transactions!$D$5:$D$1504,$A7,Transactions!$L$5:$L$1504,C$4)) | D7: =IF($A7="",0,SUMIFS(Transactions!$E$5:$E$1504,Transactions!$D$5:$D$1504,$A7,Transactions!$L$5:$L$1504,D$4)-SUMIFS(Transactions!$F$5:$F$1504,Transactions!$D$5:$D$1504,$A7,Transactions!$L$5:$L$1504,D$4)) | E7: =IF($A7="",0,SUMIFS(Transactions!$E$5:$E$1504,Transactions!$D$5:$D$1504,$A7,Transactions!$L$5:$L$1504,E$4)-SUMIFS(Transactions!$F$5:$F$1504,Transactions!$D$5:$D$1504,$A7,Transactions!$L$5:$L$1504,E$4)) | F7: =IF($A7="",0,SUMIFS(Transactions!$E$5:$E$1504,Transactions!$D$5:$D$1504,$A7,Transactions!$L$5:$L$1504,F$4)-SUMIFS(Transactions!$F$5:$F$1504,Transactions!$D$5:$D$1504,$A7,Transactions!$L$5:$L$1504,F$4)) | G7: =IF($A7="",0,SUMIFS(Transactions!$E$5:$E$1504,Transactions!$D$5:$D$1504,$A7,Transactions!$L$5:$L$1504,G$4)-SUMIFS(Transactions!$F$5:$F$1504,Transactions!$D$5:$D$1504,$A7,Transactions!$L$5:$L$1504,G$4)) | H7: =IF($A7="",0,SUMIFS(Transactions!$E$5:$E$1504,Transactions!$D$5:$D$1504,$A7,Transactions!$L$5:$L$1504,H$4)-SUMIFS(Transactions!$F$5:$F$1504,Transactions!$D$5:$D$1504,$A7,Transactions!$L$5:$L$1504,H$4)) | I7: =IF($A7="",0,SUMIFS(Transactions!$E$5:$E$1504,Transactions!$D$5:$D$1504,$A7,Transactions!$L$5:$L$1504,I$4)-SUMIFS(Transactions!$F$5:$F$1504,Transactions!$D$5:$D$1504,$A7,Transactions!$L$5:$L$1504,I$4)) | ... M7: =IF($A7="",0,SUMIFS(Transactions!$E$5:$E$1504,Transactions!$D$5:$D$1504,$A7,Transactions!$L$5:$L$1504,M$4)-SUMIFS(Transactions!$F$5:$F$1504,Transactions!$D$5:$D$1504,$A7,Transactions!$L$5:$L$1504,M$4)) | N7: =SUM(B7:M7)
A8: =IF(Setup!$A$26="","",Setup!$A$26) | B8: =IF($A8="",0,SUMIFS(Transactions!$E$5:$E$1504,Transactions!$D$5:$D$1504,$A8,Transactions!$L$5:$L$1504,B$4)-SUMIFS(Transactions!$F$5:$F$1504,Transactions!$D$5:$D$1504,$A8,Transactions!$L$5:$L$1504,B$4)) | C8: =IF($A8="",0,SUMIFS(Transactions!$E$5:$E$1504,Transactions!$D$5:$D$1504,$A8,Transactions!$L$5:$L$1504,C$4)-SUMIFS(Transactions!$F$5:$F$1504,Transactions!$D$5:$D$1504,$A8,Transactions!$L$5:$L$1504,C$4)) | D8: =IF($A8="",0,SUMIFS(Transactions!$E$5:$E$1504,Transactions!$D$5:$D$1504,$A8,Transactions!$L$5:$L$1504,D$4)-SUMIFS(Transactions!$F$5:$F$1504,Transactions!$D$5:$D$1504,$A8,Transactions!$L$5:$L$1504,D$4)) | E8: =IF($A8="",0,SUMIFS(Transactions!$E$5:$E$1504,Transactions!$D$5:$D$1504,$A8,Transactions!$L$5:$L$1504,E$4)-SUMIFS(Transactions!$F$5:$F$1504,Transactions!$D$5:$D$1504,$A8,Transactions!$L$5:$L$1504,E$4)) | F8: =IF($A8="",0,SUMIFS(Transactions!$E$5:$E$1504,Transactions!$D$5:$D$1504,$A8,Transactions!$L$5:$L$1504,F$4)-SUMIFS(Transactions!$F$5:$F$1504,Transactions!$D$5:$D$1504,$A8,Transactions!$L$5:$L$1504,F$4)) | G8: =IF($A8="",0,SUMIFS(Transactions!$E$5:$E$1504,Transactions!$D$5:$D$1504,$A8,Transactions!$L$5:$L$1504,G$4)-SUMIFS(Transactions!$F$5:$F$1504,Transactions!$D$5:$D$1504,$A8,Transactions!$L$5:$L$1504,G$4)) | H8: =IF($A8="",0,SUMIFS(Transactions!$E$5:$E$1504,Transactions!$D$5:$D$1504,$A8,Transactions!$L$5:$L$1504,H$4)-SUMIFS(Transactions!$F$5:$F$1504,Transactions!$D$5:$D$1504,$A8,Transactions!$L$5:$L$1504,H$4)) | I8: =IF($A8="",0,SUMIFS(Transactions!$E$5:$E$1504,Transactions!$D$5:$D$1504,$A8,Transactions!$L$5:$L$1504,I$4)-SUMIFS(Transactions!$F$5:$F$1504,Transactions!$D$5:$D$1504,$A8,Transactions!$L$5:$L$1504,I$4)) | ... M8: =IF($A8="",0,SUMIFS(Transactions!$E$5:$E$1504,Transactions!$D$5:$D$1504,$A8,Transactions!$L$5:$L$1504,M$4)-SUMIFS(Transactions!$F$5:$F$1504,Transactions!$D$5:$D$1504,$A8,Transactions!$L$5:$L$1504,M$4)) | N8: =SUM(B8:M8)
A9: =IF(Setup!$A$27="","",Setup!$A$27) | B9: =IF($A9="",0,SUMIFS(Transactions!$E$5:$E$1504,Transactions!$D$5:$D$1504,$A9,Transactions!$L$5:$L$1504,B$4)-SUMIFS(Transactions!$F$5:$F$1504,Transactions!$D$5:$D$1504,$A9,Transactions!$L$5:$L$1504,B$4)) | C9: =IF($A9="",0,SUMIFS(Transactions!$E$5:$E$1504,Transactions!$D$5:$D$1504,$A9,Transactions!$L$5:$L$1504,C$4)-SUMIFS(Transactions!$F$5:$F$1504,Transactions!$D$5:$D$1504,$A9,Transactions!$L$5:$L$1504,C$4)) | D9: =IF($A9="",0,SUMIFS(Transactions!$E$5:$E$1504,Transactions!$D$5:$D$1504,$A9,Transactions!$L$5:$L$1504,D$4)-SUMIFS(Transactions!$F$5:$F$1504,Transactions!$D$5:$D$1504,$A9,Transactions!$L$5:$L$1504,D$4)) | E9: =IF($A9="",0,SUMIFS(Transactions!$E$5:$E$1504,Transactions!$D$5:$D$1504,$A9,Transactions!$L$5:$L$1504,E$4)-SUMIFS(Transactions!$F$5:$F$1504,Transactions!$D$5:$D$1504,$A9,Transactions!$L$5:$L$1504,E$4)) | F9: =IF($A9="",0,SUMIFS(Transactions!$E$5:$E$1504,Transactions!$D$5:$D$1504,$A9,Transactions!$L$5:$L$1504,F$4)-SUMIFS(Transactions!$F$5:$F$1504,Transactions!$D$5:$D$1504,$A9,Transactions!$L$5:$L$1504,F$4)) | G9: =IF($A9="",0,SUMIFS(Transactions!$E$5:$E$1504,Transactions!$D$5:$D$1504,$A9,Transactions!$L$5:$L$1504,G$4)-SUMIFS(Transactions!$F$5:$F$1504,Transactions!$D$5:$D$1504,$A9,Transactions!$L$5:$L$1504,G$4)) | H9: =IF($A9="",0,SUMIFS(Transactions!$E$5:$E$1504,Transactions!$D$5:$D$1504,$A9,Transactions!$L$5:$L$1504,H$4)-SUMIFS(Transactions!$F$5:$F$1504,Transactions!$D$5:$D$1504,$A9,Transactions!$L$5:$L$1504,H$4)) | I9: =IF($A9="",0,SUMIFS(Transactions!$E$5:$E$1504,Transactions!$D$5:$D$1504,$A9,Transactions!$L$5:$L$1504,I$4)-SUMIFS(Transactions!$F$5:$F$1504,Transactions!$D$5:$D$1504,$A9,Transactions!$L$5:$L$1504,I$4)) | ... M9: =IF($A9="",0,SUMIFS(Transactions!$E$5:$E$1504,Transactions!$D$5:$D$1504,$A9,Transactions!$L$5:$L$1504,M$4)-SUMIFS(Transactions!$F$5:$F$1504,Transactions!$D$5:$D$1504,$A9,Transactions!$L$5:$L$1504,M$4)) | N9: =SUM(B9:M9)
A10: =IF(Setup!$A$28="","",Setup!$A$28) | B10: =IF($A10="",0,SUMIFS(Transactions!$E$5:$E$1504,Transactions!$D$5:$D$1504,$A10,Transactions!$L$5:$L$1504,B$4)-SUMIFS(Transactions!$F$5:$F$1504,Transactions!$D$5:$D$1504,$A10,Transactions!$L$5:$L$1504,B$4)) | C10: =IF($A10="",0,SUMIFS(Transactions!$E$5:$E$1504,Transactions!$D$5:$D$1504,$A10,Transactions!$L$5:$L$1504,C$4)-SUMIFS(Transactions!$F$5:$F$1504,Transactions!$D$5:$D$1504,$A10,Transactions!$L$5:$L$1504,C$4)) | D10: =IF($A10="",0,SUMIFS(Transactions!$E$5:$E$1504,Transactions!$D$5:$D$1504,$A10,Transactions!$L$5:$L$1504,D$4)-SUMIFS(Transactions!$F$5:$F$1504,Transactions!$D$5:$D$1504,$A10,Transactions!$L$5:$L$1504,D$4)) | E10: =IF($A10="",0,SUMIFS(Transactions!$E$5:$E$1504,Transactions!$D$5:$D$1504,$A10,Transactions!$L$5:$L$1504,E$4)-SUMIFS(Transactions!$F$5:$F$1504,Transactions!$D$5:$D$1504,$A10,Transactions!$L$5:$L$1504,E$4)) | F10: =IF($A10="",0,SUMIFS(Transactions!$E$5:$E$1504,Transactions!$D$5:$D$1504,$A10,Transactions!$L$5:$L$1504,F$4)-SUMIFS(Transactions!$F$5:$F$1504,Transactions!$D$5:$D$1504,$A10,Transactions!$L$5:$L$1504,F$4)) | G10: =IF($A10="",0,SUMIFS(Transactions!$E$5:$E$1504,Transactions!$D$5:$D$1504,$A10,Transactions!$L$5:$L$1504,G$4)-SUMIFS(Transactions!$F$5:$F$1504,Transactions!$D$5:$D$1504,$A10,Transactions!$L$5:$L$1504,G$4)) | H10: =IF($A10="",0,SUMIFS(Transactions!$E$5:$E$1504,Transactions!$D$5:$D$1504,$A10,Transactions!$L$5:$L$1504,H$4)-SUMIFS(Transactions!$F$5:$F$1504,Transactions!$D$5:$D$1504,$A10,Transactions!$L$5:$L$1504,H$4)) | I10: =IF($A10="",0,SUMIFS(Transactions!$E$5:$E$1504,Transactions!$D$5:$D$1504,$A10,Transactions!$L$5:$L$1504,I$4)-SUMIFS(Transactions!$F$5:$F$1504,Transactions!$D$5:$D$1504,$A10,Transactions!$L$5:$L$1504,I$4)) | ... M10: =IF($A10="",0,SUMIFS(Transactions!$E$5:$E$1504,Transactions!$D$5:$D$1504,$A10,Transactions!$L$5:$L$1504,M$4)-SUMIFS(Transactions!$F$5:$F$1504,Transactions!$D$5:$D$1504,$A10,Transactions!$L$5:$L$1504,M$4)) | N10: =SUM(B10:M10)
A11: Total revenue | B11: =SUM(B6:B10) | C11: =SUM(C6:C10) | D11: =SUM(D6:D10) | E11: =SUM(E6:E10) | F11: =SUM(F6:F10) | G11: =SUM(G6:G10) | H11: =SUM(H6:H10) | I11: =SUM(I6:I10) | ... N11: =SUM(N6:N10)
A13: DIRECT COSTS (cost of delivering the service)
A14: =IF(Setup!$A$29="","",Setup!$A$29) | B14: =IF($A14="",0,SUMIFS(Transactions!$F$5:$F$1504,Transactions!$D$5:$D$1504,$A14,Transactions!$L$5:$L$1504,B$4)-SUMIFS(Transactions!$E$5:$E$1504,Transactions!$D$5:$D$1504,$A14,Transactions!$L$5:$L$1504,B$4)) | C14: =IF($A14="",0,SUMIFS(Transactions!$F$5:$F$1504,Transactions!$D$5:$D$1504,$A14,Transactions!$L$5:$L$1504,C$4)-SUMIFS(Transactions!$E$5:$E$1504,Transactions!$D$5:$D$1504,$A14,Transactions!$L$5:$L$1504,C$4)) | D14: =IF($A14="",0,SUMIFS(Transactions!$F$5:$F$1504,Transactions!$D$5:$D$1504,$A14,Transactions!$L$5:$L$1504,D$4)-SUMIFS(Transactions!$E$5:$E$1504,Transactions!$D$5:$D$1504,$A14,Transactions!$L$5:$L$1504,D$4)) | E14: =IF($A14="",0,SUMIFS(Transactions!$F$5:$F$1504,Transactions!$D$5:$D$1504,$A14,Transactions!$L$5:$L$1504,E$4)-SUMIFS(Transactions!$E$5:$E$1504,Transactions!$D$5:$D$1504,$A14,Transactions!$L$5:$L$1504,E$4)) | F14: =IF($A14="",0,SUMIFS(Transactions!$F$5:$F$1504,Transactions!$D$5:$D$1504,$A14,Transactions!$L$5:$L$1504,F$4)-SUMIFS(Transactions!$E$5:$E$1504,Transactions!$D$5:$D$1504,$A14,Transactions!$L$5:$L$1504,F$4)) | G14: =IF($A14="",0,SUMIFS(Transactions!$F$5:$F$1504,Transactions!$D$5:$D$1504,$A14,Transactions!$L$5:$L$1504,G$4)-SUMIFS(Transactions!$E$5:$E$1504,Transactions!$D$5:$D$1504,$A14,Transactions!$L$5:$L$1504,G$4)) | H14: =IF($A14="",0,SUMIFS(Transactions!$F$5:$F$1504,Transactions!$D$5:$D$1504,$A14,Transactions!$L$5:$L$1504,H$4)-SUMIFS(Transactions!$E$5:$E$1504,Transactions!$D$5:$D$1504,$A14,Transactions!$L$5:$L$1504,H$4)) | I14: =IF($A14="",0,SUMIFS(Transactions!$F$5:$F$1504,Transactions!$D$5:$D$1504,$A14,Transactions!$L$5:$L$1504,I$4)-SUMIFS(Transactions!$E$5:$E$1504,Transactions!$D$5:$D$1504,$A14,Transactions!$L$5:$L$1504,I$4)) | ... M14: =IF($A14="",0,SUMIFS(Transactions!$F$5:$F$1504,Transactions!$D$5:$D$1504,$A14,Transactions!$L$5:$L$1504,M$4)-SUMIFS(Transactions!$E$5:$E$1504,Transactions!$D$5:$D$1504,$A14,Transactions!$L$5:$L$1504,M$4)) | N14: =SUM(B14:M14)
A15: =IF(Setup!$A$30="","",Setup!$A$30) | B15: =IF($A15="",0,SUMIFS(Transactions!$F$5:$F$1504,Transactions!$D$5:$D$1504,$A15,Transactions!$L$5:$L$1504,B$4)-SUMIFS(Transactions!$E$5:$E$1504,Transactions!$D$5:$D$1504,$A15,Transactions!$L$5:$L$1504,B$4)) | C15: =IF($A15="",0,SUMIFS(Transactions!$F$5:$F$1504,Transactions!$D$5:$D$1504,$A15,Transactions!$L$5:$L$1504,C$4)-SUMIFS(Transactions!$E$5:$E$1504,Transactions!$D$5:$D$1504,$A15,Transactions!$L$5:$L$1504,C$4)) | D15: =IF($A15="",0,SUMIFS(Transactions!$F$5:$F$1504,Transactions!$D$5:$D$1504,$A15,Transactions!$L$5:$L$1504,D$4)-SUMIFS(Transactions!$E$5:$E$1504,Transactions!$D$5:$D$1504,$A15,Transactions!$L$5:$L$1504,D$4)) | E15: =IF($A15="",0,SUMIFS(Transactions!$F$5:$F$1504,Transactions!$D$5:$D$1504,$A15,Transactions!$L$5:$L$1504,E$4)-SUMIFS(Transactions!$E$5:$E$1504,Transactions!$D$5:$D$1504,$A15,Transactions!$L$5:$L$1504,E$4)) | F15: =IF($A15="",0,SUMIFS(Transactions!$F$5:$F$1504,Transactions!$D$5:$D$1504,$A15,Transactions!$L$5:$L$1504,F$4)-SUMIFS(Transactions!$E$5:$E$1504,Transactions!$D$5:$D$1504,$A15,Transactions!$L$5:$L$1504,F$4)) | G15: =IF($A15="",0,SUMIFS(Transactions!$F$5:$F$1504,Transactions!$D$5:$D$1504,$A15,Transactions!$L$5:$L$1504,G$4)-SUMIFS(Transactions!$E$5:$E$1504,Transactions!$D$5:$D$1504,$A15,Transactions!$L$5:$L$1504,G$4)) | H15: =IF($A15="",0,SUMIFS(Transactions!$F$5:$F$1504,Transactions!$D$5:$D$1504,$A15,Transactions!$L$5:$L$1504,H$4)-SUMIFS(Transactions!$E$5:$E$1504,Transactions!$D$5:$D$1504,$A15,Transactions!$L$5:$L$1504,H$4)) | I15: =IF($A15="",0,SUMIFS(Transactions!$F$5:$F$1504,Transactions!$D$5:$D$1504,$A15,Transactions!$L$5:$L$1504,I$4)-SUMIFS(Transactions!$E$5:$E$1504,Transactions!$D$5:$D$1504,$A15,Transactions!$L$5:$L$1504,I$4)) | ... M15: =IF($A15="",0,SUMIFS(Transactions!$F$5:$F$1504,Transactions!$D$5:$D$1504,$A15,Transactions!$L$5:$L$1504,M$4)-SUMIFS(Transactions!$E$5:$E$1504,Transactions!$D$5:$D$1504,$A15,Transactions!$L$5:$L$1504,M$4)) | N15: =SUM(B15:M15)
A16: =IF(Setup!$A$31="","",Setup!$A$31) | B16: =IF($A16="",0,SUMIFS(Transactions!$F$5:$F$1504,Transactions!$D$5:$D$1504,$A16,Transactions!$L$5:$L$1504,B$4)-SUMIFS(Transactions!$E$5:$E$1504,Transactions!$D$5:$D$1504,$A16,Transactions!$L$5:$L$1504,B$4)) | C16: =IF($A16="",0,SUMIFS(Transactions!$F$5:$F$1504,Transactions!$D$5:$D$1504,$A16,Transactions!$L$5:$L$1504,C$4)-SUMIFS(Transactions!$E$5:$E$1504,Transactions!$D$5:$D$1504,$A16,Transactions!$L$5:$L$1504,C$4)) | D16: =IF($A16="",0,SUMIFS(Transactions!$F$5:$F$1504,Transactions!$D$5:$D$1504,$A16,Transactions!$L$5:$L$1504,D$4)-SUMIFS(Transactions!$E$5:$E$1504,Transactions!$D$5:$D$1504,$A16,Transactions!$L$5:$L$1504,D$4)) | E16: =IF($A16="",0,SUMIFS(Transactions!$F$5:$F$1504,Transactions!$D$5:$D$1504,$A16,Transactions!$L$5:$L$1504,E$4)-SUMIFS(Transactions!$E$5:$E$1504,Transactions!$D$5:$D$1504,$A16,Transactions!$L$5:$L$1504,E$4)) | F16: =IF($A16="",0,SUMIFS(Transactions!$F$5:$F$1504,Transactions!$D$5:$D$1504,$A16,Transactions!$L$5:$L$1504,F$4)-SUMIFS(Transactions!$E$5:$E$1504,Transactions!$D$5:$D$1504,$A16,Transactions!$L$5:$L$1504,F$4)) | G16: =IF($A16="",0,SUMIFS(Transactions!$F$5:$F$1504,Transactions!$D$5:$D$1504,$A16,Transactions!$L$5:$L$1504,G$4)-SUMIFS(Transactions!$E$5:$E$1504,Transactions!$D$5:$D$1504,$A16,Transactions!$L$5:$L$1504,G$4)) | H16: =IF($A16="",0,SUMIFS(Transactions!$F$5:$F$1504,Transactions!$D$5:$D$1504,$A16,Transactions!$L$5:$L$1504,H$4)-SUMIFS(Transactions!$E$5:$E$1504,Transactions!$D$5:$D$1504,$A16,Transactions!$L$5:$L$1504,H$4)) | I16: =IF($A16="",0,SUMIFS(Transactions!$F$5:$F$1504,Transactions!$D$5:$D$1504,$A16,Transactions!$L$5:$L$1504,I$4)-SUMIFS(Transactions!$E$5:$E$1504,Transactions!$D$5:$D$1504,$A16,Transactions!$L$5:$L$1504,I$4)) | ... M16: =IF($A16="",0,SUMIFS(Transactions!$F$5:$F$1504,Transactions!$D$5:$D$1504,$A16,Transactions!$L$5:$L$1504,M$4)-SUMIFS(Transactions!$E$5:$E$1504,Transactions!$D$5:$D$1504,$A16,Transactions!$L$5:$L$1504,M$4)) | N16: =SUM(B16:M16)
A17: =IF(Setup!$A$32="","",Setup!$A$32) | B17: =IF($A17="",0,SUMIFS(Transactions!$F$5:$F$1504,Transactions!$D$5:$D$1504,$A17,Transactions!$L$5:$L$1504,B$4)-SUMIFS(Transactions!$E$5:$E$1504,Transactions!$D$5:$D$1504,$A17,Transactions!$L$5:$L$1504,B$4)) | C17: =IF($A17="",0,SUMIFS(Transactions!$F$5:$F$1504,Transactions!$D$5:$D$1504,$A17,Transactions!$L$5:$L$1504,C$4)-SUMIFS(Transactions!$E$5:$E$1504,Transactions!$D$5:$D$1504,$A17,Transactions!$L$5:$L$1504,C$4)) | D17: =IF($A17="",0,SUMIFS(Transactions!$F$5:$F$1504,Transactions!$D$5:$D$1504,$A17,Transactions!$L$5:$L$1504,D$4)-SUMIFS(Transactions!$E$5:$E$1504,Transactions!$D$5:$D$1504,$A17,Transactions!$L$5:$L$1504,D$4)) | E17: =IF($A17="",0,SUMIFS(Transactions!$F$5:$F$1504,Transactions!$D$5:$D$1504,$A17,Transactions!$L$5:$L$1504,E$4)-SUMIFS(Transactions!$E$5:$E$1504,Transactions!$D$5:$D$1504,$A17,Transactions!$L$5:$L$1504,E$4)) | F17: =IF($A17="",0,SUMIFS(Transactions!$F$5:$F$1504,Transactions!$D$5:$D$1504,$A17,Transactions!$L$5:$L$1504,F$4)-SUMIFS(Transactions!$E$5:$E$1504,Transactions!$D$5:$D$1504,$A17,Transactions!$L$5:$L$1504,F$4)) | G17: =IF($A17="",0,SUMIFS(Transactions!$F$5:$F$1504,Transactions!$D$5:$D$1504,$A17,Transactions!$L$5:$L$1504,G$4)-SUMIFS(Transactions!$E$5:$E$1504,Transactions!$D$5:$D$1504,$A17,Transactions!$L$5:$L$1504,G$4)) | H17: =IF($A17="",0,SUMIFS(Transactions!$F$5:$F$1504,Transactions!$D$5:$D$1504,$A17,Transactions!$L$5:$L$1504,H$4)-SUMIFS(Transactions!$E$5:$E$1504,Transactions!$D$5:$D$1504,$A17,Transactions!$L$5:$L$1504,H$4)) | I17: =IF($A17="",0,SUMIFS(Transactions!$F$5:$F$1504,Transactions!$D$5:$D$1504,$A17,Transactions!$L$5:$L$1504,I$4)-SUMIFS(Transactions!$E$5:$E$1504,Transactions!$D$5:$D$1504,$A17,Transactions!$L$5:$L$1504,I$4)) | ... M17: =IF($A17="",0,SUMIFS(Transactions!$F$5:$F$1504,Transactions!$D$5:$D$1504,$A17,Transactions!$L$5:$L$1504,M$4)-SUMIFS(Transactions!$E$5:$E$1504,Transactions!$D$5:$D$1504,$A17,Transactions!$L$5:$L$1504,M$4)) | N17: =SUM(B17:M17)
A18: =IF(Setup!$A$33="","",Setup!$A$33) | B18: =IF($A18="",0,SUMIFS(Transactions!$F$5:$F$1504,Transactions!$D$5:$D$1504,$A18,Transactions!$L$5:$L$1504,B$4)-SUMIFS(Transactions!$E$5:$E$1504,Transactions!$D$5:$D$1504,$A18,Transactions!$L$5:$L$1504,B$4)) | C18: =IF($A18="",0,SUMIFS(Transactions!$F$5:$F$1504,Transactions!$D$5:$D$1504,$A18,Transactions!$L$5:$L$1504,C$4)-SUMIFS(Transactions!$E$5:$E$1504,Transactions!$D$5:$D$1504,$A18,Transactions!$L$5:$L$1504,C$4)) | D18: =IF($A18="",0,SUMIFS(Transactions!$F$5:$F$1504,Transactions!$D$5:$D$1504,$A18,Transactions!$L$5:$L$1504,D$4)-SUMIFS(Transactions!$E$5:$E$1504,Transactions!$D$5:$D$1504,$A18,Transactions!$L$5:$L$1504,D$4)) | E18: =IF($A18="",0,SUMIFS(Transactions!$F$5:$F$1504,Transactions!$D$5:$D$1504,$A18,Transactions!$L$5:$L$1504,E$4)-SUMIFS(Transactions!$E$5:$E$1504,Transactions!$D$5:$D$1504,$A18,Transactions!$L$5:$L$1504,E$4)) | F18: =IF($A18="",0,SUMIFS(Transactions!$F$5:$F$1504,Transactions!$D$5:$D$1504,$A18,Transactions!$L$5:$L$1504,F$4)-SUMIFS(Transactions!$E$5:$E$1504,Transactions!$D$5:$D$1504,$A18,Transactions!$L$5:$L$1504,F$4)) | G18: =IF($A18="",0,SUMIFS(Transactions!$F$5:$F$1504,Transactions!$D$5:$D$1504,$A18,Transactions!$L$5:$L$1504,G$4)-SUMIFS(Transactions!$E$5:$E$1504,Transactions!$D$5:$D$1504,$A18,Transactions!$L$5:$L$1504,G$4)) | H18: =IF($A18="",0,SUMIFS(Transactions!$F$5:$F$1504,Transactions!$D$5:$D$1504,$A18,Transactions!$L$5:$L$1504,H$4)-SUMIFS(Transactions!$E$5:$E$1504,Transactions!$D$5:$D$1504,$A18,Transactions!$L$5:$L$1504,H$4)) | I18: =IF($A18="",0,SUMIFS(Transactions!$F$5:$F$1504,Transactions!$D$5:$D$1504,$A18,Transactions!$L$5:$L$1504,I$4)-SUMIFS(Transactions!$E$5:$E$1504,Transactions!$D$5:$D$1504,$A18,Transactions!$L$5:$L$1504,I$4)) | ... M18: =IF($A18="",0,SUMIFS(Transactions!$F$5:$F$1504,Transactions!$D$5:$D$1504,$A18,Transactions!$L$5:$L$1504,M$4)-SUMIFS(Transactions!$E$5:$E$1504,Transactions!$D$5:$D$1504,$A18,Transactions!$L$5:$L$1504,M$4)) | N18: =SUM(B18:M18)
A19: Total direct costs | B19: =SUM(B14:B18) | C19: =SUM(C14:C18) | D19: =SUM(D14:D18) | E19: =SUM(E14:E18) | F19: =SUM(F14:F18) | G19: =SUM(G14:G18) | H19: =SUM(H14:H18) | I19: =SUM(I14:I18) | ... N19: =SUM(N14:N18)
A21: GROSS PROFIT (revenue − direct costs) | B21: =B11-B19 | C21: =C11-C19 | D21: =D11-D19 | E21: =E11-E19 | F21: =F11-F19 | G21: =G11-G19 | H21: =H11-H19 | I21: =I11-I19 | ... N21: =N11-N19
A22: Gross margin % | B22: =IF(B11=0,0,B21/B11) | C22: =IF(C11=0,0,C21/C11) | D22: =IF(D11=0,0,D21/D11) | E22: =IF(E11=0,0,E21/E11) | F22: =IF(F11=0,0,F21/F11) | G22: =IF(G11=0,0,G21/G11) | H22: =IF(H11=0,0,H21/H11) | I22: =IF(I11=0,0,I21/I11) | ... N22: =IF(N11=0,0,N21/N11)
A24: OPERATING EXPENSES (overheads)
A25: =IF(Setup!$A$34="","",Setup!$A$34) | B25: =IF($A25="",0,SUMIFS(Transactions!$F$5:$F$1504,Transactions!$D$5:$D$1504,$A25,Transactions!$L$5:$L$1504,B$4)-SUMIFS(Transactions!$E$5:$E$1504,Transactions!$D$5:$D$1504,$A25,Transactions!$L$5:$L$1504,B$4)) | C25: =IF($A25="",0,SUMIFS(Transactions!$F$5:$F$1504,Transactions!$D$5:$D$1504,$A25,Transactions!$L$5:$L$1504,C$4)-SUMIFS(Transactions!$E$5:$E$1504,Transactions!$D$5:$D$1504,$A25,Transactions!$L$5:$L$1504,C$4)) | D25: =IF($A25="",0,SUMIFS(Transactions!$F$5:$F$1504,Transactions!$D$5:$D$1504,$A25,Transactions!$L$5:$L$1504,D$4)-SUMIFS(Transactions!$E$5:$E$1504,Transactions!$D$5:$D$1504,$A25,Transactions!$L$5:$L$1504,D$4)) | E25: =IF($A25="",0,SUMIFS(Transactions!$F$5:$F$1504,Transactions!$D$5:$D$1504,$A25,Transactions!$L$5:$L$1504,E$4)-SUMIFS(Transactions!$E$5:$E$1504,Transactions!$D$5:$D$1504,$A25,Transactions!$L$5:$L$1504,E$4)) | F25: =IF($A25="",0,SUMIFS(Transactions!$F$5:$F$1504,Transactions!$D$5:$D$1504,$A25,Transactions!$L$5:$L$1504,F$4)-SUMIFS(Transactions!$E$5:$E$1504,Transactions!$D$5:$D$1504,$A25,Transactions!$L$5:$L$1504,F$4)) | G25: =IF($A25="",0,SUMIFS(Transactions!$F$5:$F$1504,Transactions!$D$5:$D$1504,$A25,Transactions!$L$5:$L$1504,G$4)-SUMIFS(Transactions!$E$5:$E$1504,Transactions!$D$5:$D$1504,$A25,Transactions!$L$5:$L$1504,G$4)) | H25: =IF($A25="",0,SUMIFS(Transactions!$F$5:$F$1504,Transactions!$D$5:$D$1504,$A25,Transactions!$L$5:$L$1504,H$4)-SUMIFS(Transactions!$E$5:$E$1504,Transactions!$D$5:$D$1504,$A25,Transactions!$L$5:$L$1504,H$4)) | I25: =IF($A25="",0,SUMIFS(Transactions!$F$5:$F$1504,Transactions!$D$5:$D$1504,$A25,Transactions!$L$5:$L$1504,I$4)-SUMIFS(Transactions!$E$5:$E$1504,Transactions!$D$5:$D$1504,$A25,Transactions!$L$5:$L$1504,I$4)) | ... M25: =IF($A25="",0,SUMIFS(Transactions!$F$5:$F$1504,Transactions!$D$5:$D$1504,$A25,Transactions!$L$5:$L$1504,M$4)-SUMIFS(Transactions!$E$5:$E$1504,Transactions!$D$5:$D$1504,$A25,Transactions!$L$5:$L$1504,M$4)) | N25: =SUM(B25:M25)
A26: =IF(Setup!$A$35="","",Setup!$A$35) | B26: =IF($A26="",0,SUMIFS(Transactions!$F$5:$F$1504,Transactions!$D$5:$D$1504,$A26,Transactions!$L$5:$L$1504,B$4)-SUMIFS(Transactions!$E$5:$E$1504,Transactions!$D$5:$D$1504,$A26,Transactions!$L$5:$L$1504,B$4)) | C26: =IF($A26="",0,SUMIFS(Transactions!$F$5:$F$1504,Transactions!$D$5:$D$1504,$A26,Transactions!$L$5:$L$1504,C$4)-SUMIFS(Transactions!$E$5:$E$1504,Transactions!$D$5:$D$1504,$A26,Transactions!$L$5:$L$1504,C$4)) | D26: =IF($A26="",0,SUMIFS(Transactions!$F$5:$F$1504,Transactions!$D$5:$D$1504,$A26,Transactions!$L$5:$L$1504,D$4)-SUMIFS(Transactions!$E$5:$E$1504,Transactions!$D$5:$D$1504,$A26,Transactions!$L$5:$L$1504,D$4)) | E26: =IF($A26="",0,SUMIFS(Transactions!$F$5:$F$1504,Transactions!$D$5:$D$1504,$A26,Transactions!$L$5:$L$1504,E$4)-SUMIFS(Transactions!$E$5:$E$1504,Transactions!$D$5:$D$1504,$A26,Transactions!$L$5:$L$1504,E$4)) | F26: =IF($A26="",0,SUMIFS(Transactions!$F$5:$F$1504,Transactions!$D$5:$D$1504,$A26,Transactions!$L$5:$L$1504,F$4)-SUMIFS(Transactions!$E$5:$E$1504,Transactions!$D$5:$D$1504,$A26,Transactions!$L$5:$L$1504,F$4)) | G26: =IF($A26="",0,SUMIFS(Transactions!$F$5:$F$1504,Transactions!$D$5:$D$1504,$A26,Transactions!$L$5:$L$1504,G$4)-SUMIFS(Transactions!$E$5:$E$1504,Transactions!$D$5:$D$1504,$A26,Transactions!$L$5:$L$1504,G$4)) | H26: =IF($A26="",0,SUMIFS(Transactions!$F$5:$F$1504,Transactions!$D$5:$D$1504,$A26,Transactions!$L$5:$L$1504,H$4)-SUMIFS(Transactions!$E$5:$E$1504,Transactions!$D$5:$D$1504,$A26,Transactions!$L$5:$L$1504,H$4)) | I26: =IF($A26="",0,SUMIFS(Transactions!$F$5:$F$1504,Transactions!$D$5:$D$1504,$A26,Transactions!$L$5:$L$1504,I$4)-SUMIFS(Transactions!$E$5:$E$1504,Transactions!$D$5:$D$1504,$A26,Transactions!$L$5:$L$1504,I$4)) | ... M26: =IF($A26="",0,SUMIFS(Transactions!$F$5:$F$1504,Transactions!$D$5:$D$1504,$A26,Transactions!$L$5:$L$1504,M$4)-SUMIFS(Transactions!$E$5:$E$1504,Transactions!$D$5:$D$1504,$A26,Transactions!$L$5:$L$1504,M$4)) | N26: =SUM(B26:M26)
A27: =IF(Setup!$A$36="","",Setup!$A$36) | B27: =IF($A27="",0,SUMIFS(Transactions!$F$5:$F$1504,Transactions!$D$5:$D$1504,$A27,Transactions!$L$5:$L$1504,B$4)-SUMIFS(Transactions!$E$5:$E$1504,Transactions!$D$5:$D$1504,$A27,Transactions!$L$5:$L$1504,B$4)) | C27: =IF($A27="",0,SUMIFS(Transactions!$F$5:$F$1504,Transactions!$D$5:$D$1504,$A27,Transactions!$L$5:$L$1504,C$4)-SUMIFS(Transactions!$E$5:$E$1504,Transactions!$D$5:$D$1504,$A27,Transactions!$L$5:$L$1504,C$4)) | D27: =IF($A27="",0,SUMIFS(Transactions!$F$5:$F$1504,Transactions!$D$5:$D$1504,$A27,Transactions!$L$5:$L$1504,D$4)-SUMIFS(Transactions!$E$5:$E$1504,Transactions!$D$5:$D$1504,$A27,Transactions!$L$5:$L$1504,D$4)) | E27: =IF($A27="",0,SUMIFS(Transactions!$F$5:$F$1504,Transactions!$D$5:$D$1504,$A27,Transactions!$L$5:$L$1504,E$4)-SUMIFS(Transactions!$E$5:$E$1504,Transactions!$D$5:$D$1504,$A27,Transactions!$L$5:$L$1504,E$4)) | F27: =IF($A27="",0,SUMIFS(Transactions!$F$5:$F$1504,Transactions!$D$5:$D$1504,$A27,Transactions!$L$5:$L$1504,F$4)-SUMIFS(Transactions!$E$5:$E$1504,Transactions!$D$5:$D$1504,$A27,Transactions!$L$5:$L$1504,F$4)) | G27: =IF($A27="",0,SUMIFS(Transactions!$F$5:$F$1504,Transactions!$D$5:$D$1504,$A27,Transactions!$L$5:$L$1504,G$4)-SUMIFS(Transactions!$E$5:$E$1504,Transactions!$D$5:$D$1504,$A27,Transactions!$L$5:$L$1504,G$4)) | H27: =IF($A27="",0,SUMIFS(Transactions!$F$5:$F$1504,Transactions!$D$5:$D$1504,$A27,Transactions!$L$5:$L$1504,H$4)-SUMIFS(Transactions!$E$5:$E$1504,Transactions!$D$5:$D$1504,$A27,Transactions!$L$5:$L$1504,H$4)) | I27: =IF($A27="",0,SUMIFS(Transactions!$F$5:$F$1504,Transactions!$D$5:$D$1504,$A27,Transactions!$L$5:$L$1504,I$4)-SUMIFS(Transactions!$E$5:$E$1504,Transactions!$D$5:$D$1504,$A27,Transactions!$L$5:$L$1504,I$4)) | ... M27: =IF($A27="",0,SUMIFS(Transactions!$F$5:$F$1504,Transactions!$D$5:$D$1504,$A27,Transactions!$L$5:$L$1504,M$4)-SUMIFS(Transactions!$E$5:$E$1504,Transactions!$D$5:$D$1504,$A27,Transactions!$L$5:$L$1504,M$4)) | N27: =SUM(B27:M27)
A28: =IF(Setup!$A$37="","",Setup!$A$37) | B28: =IF($A28="",0,SUMIFS(Transactions!$F$5:$F$1504,Transactions!$D$5:$D$1504,$A28,Transactions!$L$5:$L$1504,B$4)-SUMIFS(Transactions!$E$5:$E$1504,Transactions!$D$5:$D$1504,$A28,Transactions!$L$5:$L$1504,B$4)) | C28: =IF($A28="",0,SUMIFS(Transactions!$F$5:$F$1504,Transactions!$D$5:$D$1504,$A28,Transactions!$L$5:$L$1504,C$4)-SUMIFS(Transactions!$E$5:$E$1504,Transactions!$D$5:$D$1504,$A28,Transactions!$L$5:$L$1504,C$4)) | D28: =IF($A28="",0,SUMIFS(Transactions!$F$5:$F$1504,Transactions!$D$5:$D$1504,$A28,Transactions!$L$5:$L$1504,D$4)-SUMIFS(Transactions!$E$5:$E$1504,Transactions!$D$5:$D$1504,$A28,Transactions!$L$5:$L$1504,D$4)) | E28: =IF($A28="",0,SUMIFS(Transactions!$F$5:$F$1504,Transactions!$D$5:$D$1504,$A28,Transactions!$L$5:$L$1504,E$4)-SUMIFS(Transactions!$E$5:$E$1504,Transactions!$D$5:$D$1504,$A28,Transactions!$L$5:$L$1504,E$4)) | F28: =IF($A28="",0,SUMIFS(Transactions!$F$5:$F$1504,Transactions!$D$5:$D$1504,$A28,Transactions!$L$5:$L$1504,F$4)-SUMIFS(Transactions!$E$5:$E$1504,Transactions!$D$5:$D$1504,$A28,Transactions!$L$5:$L$1504,F$4)) | G28: =IF($A28="",0,SUMIFS(Transactions!$F$5:$F$1504,Transactions!$D$5:$D$1504,$A28,Transactions!$L$5:$L$1504,G$4)-SUMIFS(Transactions!$E$5:$E$1504,Transactions!$D$5:$D$1504,$A28,Transactions!$L$5:$L$1504,G$4)) | H28: =IF($A28="",0,SUMIFS(Transactions!$F$5:$F$1504,Transactions!$D$5:$D$1504,$A28,Transactions!$L$5:$L$1504,H$4)-SUMIFS(Transactions!$E$5:$E$1504,Transactions!$D$5:$D$1504,$A28,Transactions!$L$5:$L$1504,H$4)) | I28: =IF($A28="",0,SUMIFS(Transactions!$F$5:$F$1504,Transactions!$D$5:$D$1504,$A28,Transactions!$L$5:$L$1504,I$4)-SUMIFS(Transactions!$E$5:$E$1504,Transactions!$D$5:$D$1504,$A28,Transactions!$L$5:$L$1504,I$4)) | ... M28: =IF($A28="",0,SUMIFS(Transactions!$F$5:$F$1504,Transactions!$D$5:$D$1504,$A28,Transactions!$L$5:$L$1504,M$4)-SUMIFS(Transactions!$E$5:$E$1504,Transactions!$D$5:$D$1504,$A28,Transactions!$L$5:$L$1504,M$4)) | N28: =SUM(B28:M28)
A29: =IF(Setup!$A$38="","",Setup!$A$38) | B29: =IF($A29="",0,SUMIFS(Transactions!$F$5:$F$1504,Transactions!$D$5:$D$1504,$A29,Transactions!$L$5:$L$1504,B$4)-SUMIFS(Transactions!$E$5:$E$1504,Transactions!$D$5:$D$1504,$A29,Transactions!$L$5:$L$1504,B$4)) | C29: =IF($A29="",0,SUMIFS(Transactions!$F$5:$F$1504,Transactions!$D$5:$D$1504,$A29,Transactions!$L$5:$L$1504,C$4)-SUMIFS(Transactions!$E$5:$E$1504,Transactions!$D$5:$D$1504,$A29,Transactions!$L$5:$L$1504,C$4)) | D29: =IF($A29="",0,SUMIFS(Transactions!$F$5:$F$1504,Transactions!$D$5:$D$1504,$A29,Transactions!$L$5:$L$1504,D$4)-SUMIFS(Transactions!$E$5:$E$1504,Transactions!$D$5:$D$1504,$A29,Transactions!$L$5:$L$1504,D$4)) | E29: =IF($A29="",0,SUMIFS(Transactions!$F$5:$F$1504,Transactions!$D$5:$D$1504,$A29,Transactions!$L$5:$L$1504,E$4)-SUMIFS(Transactions!$E$5:$E$1504,Transactions!$D$5:$D$1504,$A29,Transactions!$L$5:$L$1504,E$4)) | F29: =IF($A29="",0,SUMIFS(Transactions!$F$5:$F$1504,Transactions!$D$5:$D$1504,$A29,Transactions!$L$5:$L$1504,F$4)-SUMIFS(Transactions!$E$5:$E$1504,Transactions!$D$5:$D$1504,$A29,Transactions!$L$5:$L$1504,F$4)) | G29: =IF($A29="",0,SUMIFS(Transactions!$F$5:$F$1504,Transactions!$D$5:$D$1504,$A29,Transactions!$L$5:$L$1504,G$4)-SUMIFS(Transactions!$E$5:$E$1504,Transactions!$D$5:$D$1504,$A29,Transactions!$L$5:$L$1504,G$4)) | H29: =IF($A29="",0,SUMIFS(Transactions!$F$5:$F$1504,Transactions!$D$5:$D$1504,$A29,Transactions!$L$5:$L$1504,H$4)-SUMIFS(Transactions!$E$5:$E$1504,Transactions!$D$5:$D$1504,$A29,Transactions!$L$5:$L$1504,H$4)) | I29: =IF($A29="",0,SUMIFS(Transactions!$F$5:$F$1504,Transactions!$D$5:$D$1504,$A29,Transactions!$L$5:$L$1504,I$4)-SUMIFS(Transactions!$E$5:$E$1504,Transactions!$D$5:$D$1504,$A29,Transactions!$L$5:$L$1504,I$4)) | ... M29: =IF($A29="",0,SUMIFS(Transactions!$F$5:$F$1504,Transactions!$D$5:$D$1504,$A29,Transactions!$L$5:$L$1504,M$4)-SUMIFS(Transactions!$E$5:$E$1504,Transactions!$D$5:$D$1504,$A29,Transactions!$L$5:$L$1504,M$4)) | N29: =SUM(B29:M29)
A30: =IF(Setup!$A$39="","",Setup!$A$39) | B30: =IF($A30="",0,SUMIFS(Transactions!$F$5:$F$1504,Transactions!$D$5:$D$1504,$A30,Transactions!$L$5:$L$1504,B$4)-SUMIFS(Transactions!$E$5:$E$1504,Transactions!$D$5:$D$1504,$A30,Transactions!$L$5:$L$1504,B$4)) | C30: =IF($A30="",0,SUMIFS(Transactions!$F$5:$F$1504,Transactions!$D$5:$D$1504,$A30,Transactions!$L$5:$L$1504,C$4)-SUMIFS(Transactions!$E$5:$E$1504,Transactions!$D$5:$D$1504,$A30,Transactions!$L$5:$L$1504,C$4)) | D30: =IF($A30="",0,SUMIFS(Transactions!$F$5:$F$1504,Transactions!$D$5:$D$1504,$A30,Transactions!$L$5:$L$1504,D$4)-SUMIFS(Transactions!$E$5:$E$1504,Transactions!$D$5:$D$1504,$A30,Transactions!$L$5:$L$1504,D$4)) | E30: =IF($A30="",0,SUMIFS(Transactions!$F$5:$F$1504,Transactions!$D$5:$D$1504,$A30,Transactions!$L$5:$L$1504,E$4)-SUMIFS(Transactions!$E$5:$E$1504,Transactions!$D$5:$D$1504,$A30,Transactions!$L$5:$L$1504,E$4)) | F30: =IF($A30="",0,SUMIFS(Transactions!$F$5:$F$1504,Transactions!$D$5:$D$1504,$A30,Transactions!$L$5:$L$1504,F$4)-SUMIFS(Transactions!$E$5:$E$1504,Transactions!$D$5:$D$1504,$A30,Transactions!$L$5:$L$1504,F$4)) | G30: =IF($A30="",0,SUMIFS(Transactions!$F$5:$F$1504,Transactions!$D$5:$D$1504,$A30,Transactions!$L$5:$L$1504,G$4)-SUMIFS(Transactions!$E$5:$E$1504,Transactions!$D$5:$D$1504,$A30,Transactions!$L$5:$L$1504,G$4)) | H30: =IF($A30="",0,SUMIFS(Transactions!$F$5:$F$1504,Transactions!$D$5:$D$1504,$A30,Transactions!$L$5:$L$1504,H$4)-SUMIFS(Transactions!$E$5:$E$1504,Transactions!$D$5:$D$1504,$A30,Transactions!$L$5:$L$1504,H$4)) | I30: =IF($A30="",0,SUMIFS(Transactions!$F$5:$F$1504,Transactions!$D$5:$D$1504,$A30,Transactions!$L$5:$L$1504,I$4)-SUMIFS(Transactions!$E$5:$E$1504,Transactions!$D$5:$D$1504,$A30,Transactions!$L$5:$L$1504,I$4)) | ... M30: =IF($A30="",0,SUMIFS(Transactions!$F$5:$F$1504,Transactions!$D$5:$D$1504,$A30,Transactions!$L$5:$L$1504,M$4)-SUMIFS(Transactions!$E$5:$E$1504,Transactions!$D$5:$D$1504,$A30,Transactions!$L$5:$L$1504,M$4)) | N30: =SUM(B30:M30)
A31: =IF(Setup!$A$40="","",Setup!$A$40) | B31: =IF($A31="",0,SUMIFS(Transactions!$F$5:$F$1504,Transactions!$D$5:$D$1504,$A31,Transactions!$L$5:$L$1504,B$4)-SUMIFS(Transactions!$E$5:$E$1504,Transactions!$D$5:$D$1504,$A31,Transactions!$L$5:$L$1504,B$4)) | C31: =IF($A31="",0,SUMIFS(Transactions!$F$5:$F$1504,Transactions!$D$5:$D$1504,$A31,Transactions!$L$5:$L$1504,C$4)-SUMIFS(Transactions!$E$5:$E$1504,Transactions!$D$5:$D$1504,$A31,Transactions!$L$5:$L$1504,C$4)) | D31: =IF($A31="",0,SUMIFS(Transactions!$F$5:$F$1504,Transactions!$D$5:$D$1504,$A31,Transactions!$L$5:$L$1504,D$4)-SUMIFS(Transactions!$E$5:$E$1504,Transactions!$D$5:$D$1504,$A31,Transactions!$L$5:$L$1504,D$4)) | E31: =IF($A31="",0,SUMIFS(Transactions!$F$5:$F$1504,Transactions!$D$5:$D$1504,$A31,Transactions!$L$5:$L$1504,E$4)-SUMIFS(Transactions!$E$5:$E$1504,Transactions!$D$5:$D$1504,$A31,Transactions!$L$5:$L$1504,E$4)) | F31: =IF($A31="",0,SUMIFS(Transactions!$F$5:$F$1504,Transactions!$D$5:$D$1504,$A31,Transactions!$L$5:$L$1504,F$4)-SUMIFS(Transactions!$E$5:$E$1504,Transactions!$D$5:$D$1504,$A31,Transactions!$L$5:$L$1504,F$4)) | G31: =IF($A31="",0,SUMIFS(Transactions!$F$5:$F$1504,Transactions!$D$5:$D$1504,$A31,Transactions!$L$5:$L$1504,G$4)-SUMIFS(Transactions!$E$5:$E$1504,Transactions!$D$5:$D$1504,$A31,Transactions!$L$5:$L$1504,G$4)) | H31: =IF($A31="",0,SUMIFS(Transactions!$F$5:$F$1504,Transactions!$D$5:$D$1504,$A31,Transactions!$L$5:$L$1504,H$4)-SUMIFS(Transactions!$E$5:$E$1504,Transactions!$D$5:$D$1504,$A31,Transactions!$L$5:$L$1504,H$4)) | I31: =IF($A31="",0,SUMIFS(Transactions!$F$5:$F$1504,Transactions!$D$5:$D$1504,$A31,Transactions!$L$5:$L$1504,I$4)-SUMIFS(Transactions!$E$5:$E$1504,Transactions!$D$5:$D$1504,$A31,Transactions!$L$5:$L$1504,I$4)) | ... M31: =IF($A31="",0,SUMIFS(Transactions!$F$5:$F$1504,Transactions!$D$5:$D$1504,$A31,Transactions!$L$5:$L$1504,M$4)-SUMIFS(Transactions!$E$5:$E$1504,Transactions!$D$5:$D$1504,$A31,Transactions!$L$5:$L$1504,M$4)) | N31: =SUM(B31:M31)
A32: =IF(Setup!$A$41="","",Setup!$A$41) | B32: =IF($A32="",0,SUMIFS(Transactions!$F$5:$F$1504,Transactions!$D$5:$D$1504,$A32,Transactions!$L$5:$L$1504,B$4)-SUMIFS(Transactions!$E$5:$E$1504,Transactions!$D$5:$D$1504,$A32,Transactions!$L$5:$L$1504,B$4)) | C32: =IF($A32="",0,SUMIFS(Transactions!$F$5:$F$1504,Transactions!$D$5:$D$1504,$A32,Transactions!$L$5:$L$1504,C$4)-SUMIFS(Transactions!$E$5:$E$1504,Transactions!$D$5:$D$1504,$A32,Transactions!$L$5:$L$1504,C$4)) | D32: =IF($A32="",0,SUMIFS(Transactions!$F$5:$F$1504,Transactions!$D$5:$D$1504,$A32,Transactions!$L$5:$L$1504,D$4)-SUMIFS(Transactions!$E$5:$E$1504,Transactions!$D$5:$D$1504,$A32,Transactions!$L$5:$L$1504,D$4)) | E32: =IF($A32="",0,SUMIFS(Transactions!$F$5:$F$1504,Transactions!$D$5:$D$1504,$A32,Transactions!$L$5:$L$1504,E$4)-SUMIFS(Transactions!$E$5:$E$1504,Transactions!$D$5:$D$1504,$A32,Transactions!$L$5:$L$1504,E$4)) | F32: =IF($A32="",0,SUMIFS(Transactions!$F$5:$F$1504,Transactions!$D$5:$D$1504,$A32,Transactions!$L$5:$L$1504,F$4)-SUMIFS(Transactions!$E$5:$E$1504,Transactions!$D$5:$D$1504,$A32,Transactions!$L$5:$L$1504,F$4)) | G32: =IF($A32="",0,SUMIFS(Transactions!$F$5:$F$1504,Transactions!$D$5:$D$1504,$A32,Transactions!$L$5:$L$1504,G$4)-SUMIFS(Transactions!$E$5:$E$1504,Transactions!$D$5:$D$1504,$A32,Transactions!$L$5:$L$1504,G$4)) | H32: =IF($A32="",0,SUMIFS(Transactions!$F$5:$F$1504,Transactions!$D$5:$D$1504,$A32,Transactions!$L$5:$L$1504,H$4)-SUMIFS(Transactions!$E$5:$E$1504,Transactions!$D$5:$D$1504,$A32,Transactions!$L$5:$L$1504,H$4)) | I32: =IF($A32="",0,SUMIFS(Transactions!$F$5:$F$1504,Transactions!$D$5:$D$1504,$A32,Transactions!$L$5:$L$1504,I$4)-SUMIFS(Transactions!$E$5:$E$1504,Transactions!$D$5:$D$1504,$A32,Transactions!$L$5:$L$1504,I$4)) | ... M32: =IF($A32="",0,SUMIFS(Transactions!$F$5:$F$1504,Transactions!$D$5:$D$1504,$A32,Transactions!$L$5:$L$1504,M$4)-SUMIFS(Transactions!$E$5:$E$1504,Transactions!$D$5:$D$1504,$A32,Transactions!$L$5:$L$1504,M$4)) | N32: =SUM(B32:M32)
A33: =IF(Setup!$A$42="","",Setup!$A$42) | B33: =IF($A33="",0,SUMIFS(Transactions!$F$5:$F$1504,Transactions!$D$5:$D$1504,$A33,Transactions!$L$5:$L$1504,B$4)-SUMIFS(Transactions!$E$5:$E$1504,Transactions!$D$5:$D$1504,$A33,Transactions!$L$5:$L$1504,B$4)) | C33: =IF($A33="",0,SUMIFS(Transactions!$F$5:$F$1504,Transactions!$D$5:$D$1504,$A33,Transactions!$L$5:$L$1504,C$4)-SUMIFS(Transactions!$E$5:$E$1504,Transactions!$D$5:$D$1504,$A33,Transactions!$L$5:$L$1504,C$4)) | D33: =IF($A33="",0,SUMIFS(Transactions!$F$5:$F$1504,Transactions!$D$5:$D$1504,$A33,Transactions!$L$5:$L$1504,D$4)-SUMIFS(Transactions!$E$5:$E$1504,Transactions!$D$5:$D$1504,$A33,Transactions!$L$5:$L$1504,D$4)) | E33: =IF($A33="",0,SUMIFS(Transactions!$F$5:$F$1504,Transactions!$D$5:$D$1504,$A33,Transactions!$L$5:$L$1504,E$4)-SUMIFS(Transactions!$E$5:$E$1504,Transactions!$D$5:$D$1504,$A33,Transactions!$L$5:$L$1504,E$4)) | F33: =IF($A33="",0,SUMIFS(Transactions!$F$5:$F$1504,Transactions!$D$5:$D$1504,$A33,Transactions!$L$5:$L$1504,F$4)-SUMIFS(Transactions!$E$5:$E$1504,Transactions!$D$5:$D$1504,$A33,Transactions!$L$5:$L$1504,F$4)) | G33: =IF($A33="",0,SUMIFS(Transactions!$F$5:$F$1504,Transactions!$D$5:$D$1504,$A33,Transactions!$L$5:$L$1504,G$4)-SUMIFS(Transactions!$E$5:$E$1504,Transactions!$D$5:$D$1504,$A33,Transactions!$L$5:$L$1504,G$4)) | H33: =IF($A33="",0,SUMIFS(Transactions!$F$5:$F$1504,Transactions!$D$5:$D$1504,$A33,Transactions!$L$5:$L$1504,H$4)-SUMIFS(Transactions!$E$5:$E$1504,Transactions!$D$5:$D$1504,$A33,Transactions!$L$5:$L$1504,H$4)) | I33: =IF($A33="",0,SUMIFS(Transactions!$F$5:$F$1504,Transactions!$D$5:$D$1504,$A33,Transactions!$L$5:$L$1504,I$4)-SUMIFS(Transactions!$E$5:$E$1504,Transactions!$D$5:$D$1504,$A33,Transactions!$L$5:$L$1504,I$4)) | ... M33: =IF($A33="",0,SUMIFS(Transactions!$F$5:$F$1504,Transactions!$D$5:$D$1504,$A33,Transactions!$L$5:$L$1504,M$4)-SUMIFS(Transactions!$E$5:$E$1504,Transactions!$D$5:$D$1504,$A33,Transactions!$L$5:$L$1504,M$4)) | N33: =SUM(B33:M33)
